Workbook

Sheet Final set of papers
A1: Title | B1: ref doi | C1: Library | D1: Tool's name | E1: What - Technology Dependecy | F1: What - Which techno | G1: What - Defects (Categories) | H1: When | I1: Where - Granularity | J1: Where - Level | K1: How - Techniques | L1: How - Categories of techniques | M1: How - Lifecycle | N1: Tool based ? | O1: Data sets / Replication packages | P1: Ranks | Q1: Year | R1: Code access | S1: Maturity | T1: Links
A2: Does your configuration code smell? | B2: https://dl.acm.org/doi/pdf/10.1145/2901739.2901761 | C2: acm (done) | D2: Puppeteer | E2: Technology Specifi - TS | F2: Puppet | G2: 2-3- Language constructs, 2-1- Naming & conventions, 1-3- Code structure, 2-2- Syntax & Formatting, 1- Structural Quality, 2- Syntactic & Linguistic Quality, 1-1- Abstraction issues, 1-2- Modularity & Organization | H2: Implementation, Design | I2: Script, Module | J2: Config management | K2: Regular Expressions - RegX | L2: 1 - Rule-Based and Pattern-Matching Approaches | M2: Static | N2: Yes | O2: https://github.com/tushartushar/Puppeteer | P2: RankA | Q2: {=IF(A2:A945="","", IFERROR( VLOOKUP(A2:A945, {'All papers'!C:C, 'All papers'!A:A}, 2, FALSE), "Not Found" ) )} -> 2016 | R2: WhiteBox | S2: Both | T2: Github
D3: PuppetLint | O3: https://github.com/tushartushar/configSmellData
A4: Gang of Eight: A Defect Taxonomy for Infrastructure as Code Scripts | B4: https://ieeexplore.ieee.org/document/9284113 | C4: ieee (done) | D4: ACID | E4: Technology Specifi - TS | F4: Puppet | G4: 8-1- Program Flow, 7-1- Configuration Data, 4-3- Dependecies & integration, 6-1- Code Readability, 9-3- Infra components, 4-1- Idempotency & State management, 3- Security, 4- Operational Quality, 8- Control Flow & Logic, 7- Data & Variable management, 6- Maintability & Documentation, 9- Domain Specific Issues | H4: Implementation | I4: Script | J4: Config management | K4: Regular Expressions - RegX | L4: 1 - Rule-Based and Pattern-Matching Approaches | M4: Static | N4: Yes | O4: https://hub.docker.com/r/akondrahman/acid-puppet https://figshare.com/s/b2633bd4b1929267a451 | P4: RankA* | Q4: 2020 | R4: WhiteBox | S4: Code access | T4: Figshare, Docker hub
A5: DeepIaC: deep learning-based linguistic anti-pattern detection in IaC | B5: https://dl.acm.org/doi/10.1145/3416505.3423564 | C5: acm (done) | D5: DeepIaC | E5: Technology Specifi - TS | F5: Ansible | G5: 2-1- Naming & conventions, 2- Syntactic & Linguistic Quality | H5: Implementation | I5: Script | J5: Config management | K5: Deep Learning - DL | L5: 4 - Statistical and Learning-Based Methods | M5: Static | N5: Yes | O5: https://github.com/SODALITE-EU/defect-prediction | P5: RankA* | Q5: 2020 | R5: WhiteBox | S5: Code access | T5: Github
A6: Polyglot Code Smell Detection for Infrastructure as Code with GLITCH; GLITCH: Automated Polyglot Security Smell Detection in Infrastructure as Code | B6: https://www.computer.org/csdl/proceedings-article/ase/2023/299600c042/1SBGsb6PvS8 https://dl.acm.org/doi/10.1145/3551349.3556945 | C6: acm (done) | D6: Glitch | E6: Technology Agnostic - TA | F6: Multi (for TA) | G6: 6-1- Code Readability, 2-2- Syntax & Formatting, 1-3- Code structure, 7-2- Vraibale management, 1-1- Abstraction issues, 1- Structural Quality, 2- Syntactic & Linguistic Quality, 6- Maintability & Documentation, 7- Data & Variable management, 3- Security | H6: Implementation | I6: Script | J6: Other | K6: Pattern Matching, Regular Expressions - RegX | L6: 1 - Rule-Based and Pattern-Matching Approaches | M6: Static | N6: Yes | O6: https://figshare.com/articles/dataset/GLITCH_Replication_Package_with_Code_and_Datasets_ASE_2022_/19726603/2?file=36939973 | P6: RankA* | Q6: 2023 | R6: WhiteBox | S6: Both | T6: Figshare
A7: Smelly variables in ansible infrastructure code: detection, prevalence, and lifetime | B7: https://dl.acm.org/doi/10.1145/3524842.3527964 | C7: acm (done) | D7: Smelly variables | E7: Technology Specifi - TS | F7: Ansible | G7: 7-2- Vraibale management, 7- Data & Variable management | H7: Implementation | I7: Script | J7: Config management | K7: Program Dependncy Graph - PDG | L7: 2 - Graph-Based Analyses | M7: Static | N7: Yes | O7: https://figshare.com/articles/dataset/Replication_package_for_Smelly_Variables_in_Ansible_Infrastructure_Code_Detection_Prevalence_and_Lifetime_/18819074 | P7: RankA | Q7: 2022 | R7: WhiteBox | S7: Dataset | T7: Figshare
A8: Source Code Properties of Defective Infrastructure as Code Scripts | B8: https://arxiv.org/abs/1810.09605 https://www.sciencedirect.com/science/article/pii/S0950584919300965 https://dl.acm.org/doi/10.1016/j.infsof.2019.04.013 | C8: acm (done) | D8: -------------- | E8: Technology Specifi - TS | F8: Puppet | G8: 2-3- Language constructs, 2- Syntactic & Linguistic Quality | H8: Implementation | I8: Script | J8: Config management | K8: Statistical Learners | L8: 4 - Statistical and Learning-Based Methods | M8: Static | N8: Yes | O8: https://figshare.com/s/ad26e370c833e8aa9712 | P8: Journal | Q8: 2019 | R8: WhiteBox | S8: Dataset | T8: Figshare
A9: As Code Testing: Characterizing Test Quality in Open Source Ansible Development | B9: https://ieeexplore.ieee.org/document/9787876 | C9: ieee (done) | D9: TAMA | E9: Technology Specifi - TS | F9: Ansible | G9: 9-3- Infra components, 4-3- Dependecies & integration, 4-1- Idempotency & State management, 5-1- Resource Optimization, 5-2- Scalability, 6-1- Code Readability, 9- Domain Specific Issues, 6- Maintability & Documentation, 4- Operational Quality, 5- Performance & Resource management, 1- Structural Quality, 2- Syntactic & Linguistic Quality, 3- Security | H9: Implementation | I9: Script | J9: Config management | K9: Pattern Algorithms | L9: 1 - Rule-Based and Pattern-Matching Approaches | M9: Static | N9: Yes | O9: https://github.com/akondrahman/IaCTesting https://figshare.com/s/4aa50ec7c34c18c71223 https://hub.docker.com/r/talismanic/tama | P9: RankA | Q9: 2022 | R9: WhiteBox | S9: Both | T9: Figshare, Docker hub, Github
A10: State Reconciliation Defects in Infrastructure as Code | B10: https://dl.acm.org/doi/10.1145/3660790 | C10: acm (done) | D10: -------------- | E10: Technology Agnostic - TA | F10: Multi (for TA) | G10: 4-3- Dependecies & integration, 8-1- Program Flow, 4-1- Idempotency & State management, 9-3- Infra components, 9-2- Cloud Provider Specfic, 4-2- Error Handling & Reliability, 7-2- Vraibale management, 8-2- Function & Method Logic, 3-1- Authentication & Authorization, 3-2- Secrets Management, 2-3- Language constructs, 5- Performance & Resource management, 2- Syntactic & Linguistic Quality, 4- Operational Quality, 7- Data & Variable management, 8- Control Flow & Logic, 9- Domain Specific Issues, 3- Security | H10: Runtime | I10: Script | J10: Other | K10: Other | L10: 5 - Testing & Excution based | M10: Hybrid | N10: Yes | O10: https://figshare.com/articles/dataset/State_Reconciliation_Defects_in_Infrastructure_as_Code/24129996?file=44810890 | P10: RankA* | Q10: 2024 | R10: WhiteBox | S10: Both | T10: Figshare
A11: Toward a catalog of software quality metrics for infrastructure code | B11: https://www.sciencedirect.com/science/article/pii/S0164121220301618 | C11: science direct (done) | D11: -------------- | E11: Technology Agnostic - TA | F11: Ansible | G11: 1-3- Code structure, 6-1- Code Readability, 2-2- Syntax & Formatting, 8-1- Program Flow, 8-2- Function & Method Logic, 4-1- Idempotency & State management, 3-1- Authentication & Authorization, 6-3- Code Reusability, 1-2- Modularity & Organization, 7-2- Vraibale management, 3-3- Network Security, 2-3- Language constructs, 6-2- Version control & Compatibility, 4-2- Error Handling & Reliability, 4-3- Dependecies & integration, 3-4- Cryptography & Integrity, 2-1- Naming & conventions, 1- Structural Quality, 2- Syntactic & Linguistic Quality, 3- Security, 4- Operational Quality, 6- Maintability & Documentation, 7- Data & Variable management, 8- Control Flow & Logic | H11: Implementation | I11: Script | J11: Config management | K11: NA | L11: NA | M11: NA | N11: No | O11: Not available | Q11: 2020 | R11: NA | S11: Not available | T11: NA
A12: Smells-sus: Sustainability Smells in IaC | B12: https://arxiv.org/abs/2501.07676 https://www.computer.org/csdl/proceedings-article/msr/2025/018300a801/27vTr57za7K https://ieeexplore.ieee.org/document/11025603 | C12: ieee (done) | D12: -------------- | E12: Technology Specifi - TS | F12: Terraform | G12: 5-1- Resource Optimization, 5-2- Scalability, 5-3- Lifecycle management, 4-1- Idempotency & State management, 1-2- Modularity & Organization, 5- Performance & Resource management, 4- Operational Quality, 1- Structural Quality | H12: Implementation | I12: Script | J12: Provisioning | K12: Regular Expressions - RegX | L12: 1 - Rule-Based and Pattern-Matching Approaches | M12: Static | N12: Yes | O12: https://zenodo.org/records/14020461 | Q12: 2025 | R12: WhiteBox | S12: Both | T12: Zenodo
A13: Security Smells in Ansible and Chef Scripts: A Replication Study | B13: https://dl.acm.org/doi/10.1145/3408897 | C13: acm (done) | D13: SLAC | E13: Technology Dependent - TD | F13: Chef, Ansible | G13: 3-1- Authentication & Authorization, 3-2- Secrets Management, 3-3- Network Security, 3-4- Cryptography & Integrity, 2-3- Language constructs, 3- Security, 2- Syntactic & Linguistic Quality | H13: Implementation | I13: Script | J13: Config management | K13: Regular Expressions - RegX | L13: 1 - Rule-Based and Pattern-Matching Approaches | M13: Static | N13: Yes | O13: https://figshare.com/articles/dataset/Dataset_for_Security_Smells_for_Ansible_and_Chef_Scripts_A_Replication_Study_/8085755 | P13: Journal | Q13: 2021 | R13: WhiteBox | S13: Dataset | T13: Figshare
A14: Rehearsal: a configuration verification tool for puppet | B14: https://dl.acm.org/doi/10.1145/2908080.2908083 | C14: acm | D14: Rehearsal | E14: Technology Specifi - TS | F14: Puppet | G14: 4-1- Idempotency & State management, 4-2- Error Handling & Reliability, 4-3- Dependecies & integration, 4- Operational Quality | H14: Implementation | I14: Script | J14: Config management | K14: Resource Graph - RG, SMT solvers | L14: 3 - Formal Methods, 2 - Graph-Based Analyses | M14: Static | N14: Yes | O14: https://github.com/plasma-umass/Rehearsal/ | Q14: 2016 | R14: WhiteBox | S14: Both | T14: Github
A18: Within-Project Defect Prediction of Infrastructure-as-Code Using Product and Process Metrics | B18: https://ieeexplore.ieee.org/document/9321740 | C18: ieee (done) | D18: RADON | E18: Technology Specifi - TS | F18: Ansible | G18: 1- Structural Quality, 2- Syntactic & Linguistic Quality, 6- Maintability & Documentation, 8- Control Flow & Logic, 7- Data & Variable management | H18: Implementation | I18: Script | J18: Config management | K18: Machine Learning - ML | L18: 4 - Statistical and Learning-Based Methods | M18: Static | N18: Yes | O18: https://www.kaggle.com/datasets/stefadp/ansibledefectsprediction https://github.com/stefanodallapalma/TSE-2020-05-0217 https://github.com/radon-h2020/radon-defect-prediction-api | Q18: 2022 | R18: WhiteBox | S18: Both | T18: Kaggle, Github
A19: Defuse: A Data Annotator and Model Builder for Software Defect Prediction | B19: https://ieeexplore.ieee.org/document/9978237 | C19: ieee (done) | D19: DEFUSE | E19: Technology Agnostic - TA | F19: Ansible, TOSCA | G19: 8-1- Program Flow, 7-1- Configuration Data, 4-3- Dependecies & integration, 6-1- Code Readability, 9-3- Infra components, 4-1- Idempotency & State management, 3- Security, 4- Operational Quality, 8- Control Flow & Logic, 7- Data & Variable management, 6- Maintability & Documentation, 9- Domain Specific Issues | H19: Implementation | I19: Script | J19: Config management | K19: Machine Learning - ML | L19: 4 - Statistical and Learning-Based Methods | M19: Static | N19: Yes | O19: https://github.com/radon-h2020/radon-defuse | P19: RankA (short paper) | Q19: 2022 | R19: WhiteBox | S19: Both | T19: Github
A20: TerraMetrics: An Open Source Tool for Infrastructure-as-Code (IaC) Quality Metrics in Terraform | B20: https://dl.acm.org/doi/10.1145/3643916.3644439 | C20: acm (done) | D20: Terrametrics | E20: Technology Specifi - TS | F20: Terraform | G20: 1-3- Code structure, 2-2- Syntax & Formatting, 7-2- Vraibale management, 2-3- Language constructs, 4-3- Dependecies & integration, 6-1- Code Readability, 8-1- Program Flow, 8-2- Function & Method Logic, 4-2- Error Handling & Reliability, 1- Structural Quality, 2- Syntactic & Linguistic Quality, 4- Operational Quality, 6- Maintability & Documentation, 7- Data & Variable management, 8- Control Flow & Logic | H20: Implementation | I20: Script | J20: Provisioning | K20: AST traversal, Visitor Pattern | L20: 2 - Graph-Based Analyses | M20: Static | N20: Yes | O20: https://github.com/stilab-ets/terametrics | P20: RankA | Q20: 2024 | R20: WhiteBox | S20: Both | T20: Github
A21: Repairing Infrastructure-as-Code using Large Language Models | B21: https://ieeexplore.ieee.org/document/10734039 | C21: ieee (done) | D21: -------------- | E21: Technology Specifi - TS | F21: Terraform | G21: 3- Security | H21: Implementation | I21: Script | J21: Provisioning | K21: LLMs | L21: 4 - Statistical and Learning-Based Methods | M21: Static | N21: Yes | O21: Not available | Q21: 2024 | R21: WhiteBox | S21: Not available | T21: NA
A22: Security in DevSecOps: Applying Tools and Machine Learning to Verification and Monitoring Steps | B22: https://dl.acm.org/doi/10.1145/3578245.3584943 | C22: acm (done) | D22: - IaC Scan Runner - LOMOS | E22: Technology Specifi - TS | F22: Ansible | G22: 3- Security | H22: Implementation, Runtime | I22: Script | J22: Config management | K22: Rule-based checks, NLP | L22: 1 - Rule-Based and Pattern-Matching Approaches, 4 - Statistical and Learning-Based Methods | M22: Hybrid | N22: Yes | O22: https://github.com/xlab-si/iac-scan-runner https://xlab-si.github.io/iac-scanner-docs/02-runner.html | P22: RankB (short paper) | Q22: 2023 | R22: WhiteBox | S22: Both | T22: Github
A23: InfraFix: Technology-Agnostic Repair of Infrastructure as Code | B23: https://dl.acm.org/doi/10.1145/3713081.3731735 https://arxiv.org/abs/2503.17220 https://conf.researchr.org/details/issta-2025/issta-2025-tool-demonstrations/15/InfraFix-Technology-Agnostic-Repair-of-Infrastructure-as-Codehttps://dl.acm.org/doi/10.1145/3713081.3731735 | C23: acm (done) | D23: InfraFix | E23: Technology Agnostic - TA | F23: Multi (for TA) | G23: 3- Security, 7- Data & Variable management, 8- Control Flow & Logic | H23: Implementation | I23: Script | J23: Other | K23: SMT solvers | L23: 3 - Formal Methods | M23: Static | N23: Yes | O23: https://zenodo.org/records/15198041 | P23: RankA (short paper) | Q23: 2025 | R23: WhiteBox | S23: Both | T23: Zenodo
A24: Towards Sustainable Cloud Deployments: A Cost (Anti)Patterns Catalog for Terraform and Cloudformation | B24: https://papers.ssrn.com/sol3/papers.cfm?abstract_id=5137165 | C24: Not peer reviewed | D24: IaC-Cost Linter | E24: Technology Specifi - TS | F24: Terraform, Cloud Formation | G24: 5-1- Resource Optimization, 5-3- Lifecycle management, 9-2- Cloud Provider Specfic, 9- Domain Specific Issues, 5- Performance & Resource management | H24: Implementation | I24: Script | J24: Provisioning | K24: Regular Expressions - RegX | L24: 1 - Rule-Based and Pattern-Matching Approaches | M24: Static | N24: Yes | O24: https://zenodo.org/records/11319775 (dataset of cost awerness) https://github.com/search-rug/iac-cost-linter/ https://zenodo.org/records/14501830 (IaC cost patterns) | Q24: 2025 | R24: WhiteBox | S24: Both | T24: Github, Zenodo
A26: A Framework for Measuring the Quality of Infrastructure-as-Code Scripts | B26: https://arxiv.org/abs/2502.03127 | C26: Not peer reviewed | D26: ------------- (Freamwork for IaC quality based on the standard ISO/IEC 25010:2011⁦) | E26: Technology Specifi - TS | F26: Ansible | G26: 6-1- Code Readability, 1-3- Code structure, 1-2- Modularity & Organization, 4-2- Error Handling & Reliability, 6-2- Version control & Compatibility, 2-1- Naming & conventions, 2-2- Syntax & Formatting, 8-2- Function & Method Logic, 8-1- Program Flow, 3-2- Secrets Management, 3-3- Network Security, 3-4- Cryptography & Integrity, 4-3- Dependecies & integration, 4-1- Idempotency & State management, 7-2- Vraibale management, 1- Structural Quality, 2- Syntactic & Linguistic Quality, 3- Security, 4- Operational Quality, 6- Maintability & Documentation, 7- Data & Variable management, 8- Control Flow & Logic | H26: Implementation | I26: Script | J26: Config management | L26: 1 - Rule-Based and Pattern-Matching Approaches, 4 - Statistical and Learning-Based Methods | M26: Static | N26: Yes | O26: https://figshare.com/s/b78d2c82767ab7d86beb | Q26: 2025 | R26: WhiteBox | S26: Both | T26: Figshare
A35: Statically Inferring Usage Bounds for Infrastructure as Code | B35: https://link.springer.com/chapter/10.1007/978-3-031-86695-1_6 https://link.springer.com/chapter/10.1007/978-3-031-86695-1_6 | C35: springer | D35: IaCAnalysis (Cost prediction) | E35: Technology Specifi - TS | F35: Cloud Formation | G35: 5-1- Resource Optimization, 5- Performance & Resource management | H35: Implementation | I35: Project | J35: Provisioning | K35: SMT solvers, Resource Graph - RG | L35: 2 - Graph-Based Analyses, 3 - Formal Methods | M35: Static | N35: Yes | O35: https://zenodo.org/records/10173400 https://github.com/Barnard-PL-Labs/IaCAnalysis/tree/main/pipr_dataset | Q35: 2024 | R35: WhiteBox | S35: Both | T35: Github, Zenodo
A36: A Comparative Study on the Security of Kubernetes Deployments | B36: https://ieeexplore.ieee.org/document/10592468 | C36: ieee | D36: kubesecurity-scanner | E36: Technology Specifi - TS | F36: Kubernetes | G36: 3-1- Authentication & Authorization, 3-2- Secrets Management, 3-3- Network Security, 5-1- Resource Optimization, 3- Security, 5- Performance & Resource management | H36: Implementation | I36: Project | J36: Orchestration | K36: Other | L36: 6 - Other | M36: Static | N36: Yes | O36: https://github.com/kamieniarzk/kube-security-scanner | P36: RankB | Q36: 2024 | R36: WhiteBox | S36: Both | T36: Github
A47: A Pilot Study of Testing Infrastructure as Code for Cloud Systems | B47: https://ieeexplore.ieee.org/document/10479426 | C47: ieee (done) | D47: ------------- (Server IaC test types) | E47: Technology Agnostic - TA | F47: Multi (for TA) | G47: 8-2- Function & Method Logic, 4-3- Dependecies & integration, 7- Data & Variable management, 4-2- Error Handling & Reliability, 3-1- Authentication & Authorization, 3-2- Secrets Management, 3-3- Network Security, 3- Security, 4- Operational Quality, 8- Control Flow & Logic | H47: Implementation | I47: Script | J47: Other | K47: NA | L47: NA | M47: NA | N47: No | O47: https://github.com/nabhan-au/Testing-IaC-Research/tree/main | P47: RankC (short paper) | Q47: 2023 | R47: NA | S47: Dataset | T47: Github
A54: An Empirical Study of Task Infections in Ansible Scripts | B54: https://akondrahman.github.io/files/papers/emse2024-tidal.pdf https://link.springer.com/article/10.1007/s10664-023-10432-6 https://dl.acm.org/doi/10.1007/s10664-023-10432-6 | C54: springer (done) | D54: TIDAL (Task Infection Detector for Ansible Scripts) | E54: Technology Specifi - TS | F54: Ansible | G54: 3-1- Authentication & Authorization, 3-2- Secrets Management, 3-4- Cryptography & Integrity, 3-3- Network Security, 9-2- Cloud Provider Specfic, 9-3- Infra components, 3- Security, 9- Domain Specific Issues | H54: Implementation | I54: Script | J54: Config management | K54: Pattern Matching, Data Dependecy Graph - DDG | L54: 1 - Rule-Based and Pattern-Matching Approaches, 2 - Graph-Based Analyses | M54: Static | N54: Yes | O54: https://figshare.com/s/c9d7b8aa973f53f02234?file=42146865 | Q54: 2023 | R54: WhiteBox | S54: Both | T54: Figshare
A60: Unearthing Semantic Checks for Cloud Infrastructure-as-Code Programs | B60: https://dl.acm.org/doi/10.1145/3694715.3695974 | C60: acm (done) | D60: Zodiac (Very good tool) | E60: Technology Dependent - TD | F60: Terraform | G60: 9- Domain Specific Issues | H60: Runtime | I60: Script | J60: Provisioning | K60: Configuration mining, LLMs, SMT solvers, Resource Graph - RG | L60: 4 - Statistical and Learning-Based Methods, 2 - Graph-Based Analyses, 3 - Formal Methods | M60: Dynamic | N60: Yes | O60: https://github.com/824728350/Zodiac | P60: RankA* | Q60: 2025 | R60: WhiteBox | S60: Both | T60: Github
A61: KubeHound: Detecting Microservices’ Security Smells in Kubernetes Deployments | B61: https://www.mdpi.com/1999-5903/15/7/228 | C61: other | D61: KubeHound | E61: Technology Specifi - TS | F61: Kubernetes | G61: 3-1- Authentication & Authorization, 3-2- Secrets Management, 3-3- Network Security, 3-4- Cryptography & Integrity, 3- Security | H61: Implementation | I61: Project | J61: Orchestration | L61: 1 - Rule-Based and Pattern-Matching Approaches, 2 - Graph-Based Analyses, 5 - Testing & Excution based | M61: Hybrid | N61: Yes | O61: https://github.com/di-unipi-socc/kube-hound https://github.com/di-unipi-socc/kube-hound/tree/master/data/examples https://archive.softwareheritage.org/browse/origin/directory/?origin_url=https://github.com/di-unipi-socc/kube-hound&path=data/examples | P61: Journal | Q61: 2023 | R61: WhiteBox | S61: Both | T61: Github
A67: Towards a Taxonomy of Infrastructure as Code Misconfigurations: An Ansible Study | B67: https://drive.google.com/file/d/101WCE65iQBGi4cWxln1_3Y2xKRb-2DUc/view?usp=sharing https://link.springer.com/chapter/10.1007/978-3-031-72578-4_5 | C67: springer (done) | D67: ------------- | E67: Technology Agnostic - TA | F67: Ansible | G67: 4-3- Dependecies & integration, 4-1- Idempotency & State management, 7-1- Configuration Data, 7-2- Vraibale management, 3-2- Secrets Management, 6-2- Version control & Compatibility, 3- Security, 4- Operational Quality, 6- Maintability & Documentation, 7- Data & Variable management | H67: Implementation | I67: Module | J67: Config management | K67: Other | L67: 6 - Other | M67: Static | N67: Yes | O67: https://github.com/SODALITE-EU/defect-prediction https://zenodo.org/records/13147770 | P67: Journal | Q67: 2025 | R67: WhiteBox | S67: Both | T67: Github, Zenodo
A68: Automated Infrastructure as Code Program Testing | B68: https://ieeexplore.ieee.org/document/10516612 | C68: ieee (done) | D68: ProTI | E68: Technology Dependent - TD | F68: Pulumi | G68: 4-2- Error Handling & Reliability, 4-3- Dependecies & integration, 7-1- Configuration Data, 2-3- Language constructs, 7- Data & Variable management, 2- Syntactic & Linguistic Quality, 4- Operational Quality | H68: Runtime, Implementation | I68: Script | J68: Provisioning | K68: Tests | L68: 6 - Other | M68: Dynamic | N68: Yes | O68: https://zenodo.org/records/14203377 https://github.com/proti-iac/proti/tree/v1.3.0 | P68: Journal | Q68: 2024 | R68: WhiteBox | S68: Code access | T68: Github, Zenodo
A69: Detecting and Characterizing Propagation of Security Weaknesses in Puppet-Based Infrastructure Management | B69: https://dl.acm.org/doi/10.1109/TSE.2023.3265962 | C69: acm (done) | D69: TaintPup | E69: Technology Specifi - TS | F69: Puppet | G69: 3- Security, 3-2- Secrets Management, 3-4- Cryptography & Integrity, 3-1- Authentication & Authorization, 3-3- Network Security | H69: Implementation | I69: Script | J69: Config management | K69: Data Dependecy Graph - DDG, Regular Expressions - RegX | L69: 2 - Graph-Based Analyses, 1 - Rule-Based and Pattern-Matching Approaches | M69: Static | N69: Yes | O69: Not available | P69: Journal | Q69: 2023 | R69: WhiteBox | S69: Not available | T69: NA
A70: Patterns of Multi-Container Composition for Service Orchestration with Docker Compose | B70: http://arxiv.org/abs/2305.11293 https://link.springer.com/article/10.1007/s10664-024-10462-8 | C70: springer (done) | D70: ------------- | E70: Technology Specifi - TS | F70: Docker-compose | G70: 6-3- Code Reusability, 1-3- Code structure, 1-1- Abstraction issues, 1-2- Modularity & Organization, 3-4- Cryptography & Integrity, 3-3- Network Security, 5-3- Lifecycle management, 4-3- Dependecies & integration, 4-1- Idempotency & State management, 9-3- Infra components, 5-2- Scalability, 9- Domain Specific Issues, 4- Operational Quality, 3- Security, 1- Structural Quality, 5- Performance & Resource management, 6- Maintability & Documentation | H70: Design, Implementation | I70: Project | J70: Orchestration | K70: NA | L70: NA | M70: NA | N70: No | O70: https://zenodo.org/records/10648448 | P70: Journal | Q70: 2024 | R70: NA | S70: Both | T70: Zenodo
A71: Exploring LLM-Based Automated Repairing of Ansible Script in Edge-Cloud Infrastructures | B71: https://ieeexplore.ieee.org/abstract/document/10376418 | C71: ieee (done) | D71: ------------- | E71: Technology Specifi - TS | F71: Ansible | G71: 4- Operational Quality | H71: Implementation | I71: Script | J71: Config management | K71: LLMs | L71: 4 - Statistical and Learning-Based Methods | M71: Static | N71: Yes | O71: Not available | P71: Journal | Q71: 2023 | R71: WhiteBox | S71: Not available | T71: NA
A72: An Empirical Study on Kubernetes Operator Bugs | B72: https://dl.acm.org/doi/10.1145/3650212.3680396 | C72: acm | D72: ------------- | E72: Technology Specifi - TS | F72: Kubernetes | G72: 4- Operational Quality | H72: Implementation | I72: Module | J72: Orchestration | K72: NA | L72: NA | M72: NA | N72: No | O72: yes (list of bugs) https://zenodo.org/records/13340387 | P72: RankA | Q72: 2024 | R72: NA | S72: Dataset | T72: Zenodo
A73: Control and Data Flow in Security Smell Detection for Infrastructure as Code: Is It Worth the Effort? | B73: https://ieeexplore.ieee.org/document/10174011 | C73: ieee (done) | D73: GASEL | E73: Technology Specifi - TS | F73: Ansible | G73: 3- Security | H73: Implementation | I73: Project | J73: Config management | K73: Control Flow Graph, Program Dependncy Graph - PDG | L73: 2 - Graph-Based Analyses | M73: Static | N73: Yes | O73: Andromeda dataset + Saavedra et al. [12]. https://figshare.com/articles/dataset/Replication_package_for_Control_and_Data_Flow_in_Security_Smell_Detection_for_Infrastructure_as_Code_Is_It_Worth_the_Effort_/21929856 | P73: RankA | Q73: 2023 | R73: WhiteBox | S73: Both | T73: Figshare
A74: On the Prevalence, Co-occurrence, and Impact of Infrastructure-as-Code Smells | B74: https://ieeexplore.ieee.org/document/10589858 | C74: ieee (done) | D74: Puppeteer + PuppetLint | E74: Technology Specifi - TS | F74: Puppet | G74: 1- Structural Quality | H74: Design, Implementation | I74: Script, Module | J74: Config management | K74: Rule-based checks, AST traversal | L74: 1 - Rule-Based and Pattern-Matching Approaches, 2 - Graph-Based Analyses | M74: Static | N74: Yes | O74: https://zenodo.org/records/10060209 | P74: RankA | Q74: 2024 | R74: WhiteBox | S74: Both | T74: Figshare
A75: Fine-Grained Just-In-Time Defect Prediction at the Block Level in Infrastructure-as-Code (IaC) | Proceedings of the 21st International Conference on Mining Software Repositories | B75: https://dl.acm.org/doi/10.1145/3643991.3644934 | C75: acm (done) | D75: ------------- | E75: Technology Specifi - TS | F75: Terraform | G75: 1- Structural Quality, 1-3- Code structure, 4- Operational Quality, 4-2- Error Handling & Reliability | H75: Design | I75: Project | J75: Provisioning | K75: Machine Learning - ML | L75: 4 - Statistical and Learning-Based Methods | M75: Static | N75: Yes | O75: https://figshare.com/s/facf0404c96b32274a35?file=44159249 | P75: RankA | Q75: 2024 | R75: WhiteBox | S75: Both | T75: Figshare
A76: Smoke Testing of Cloud Systems | B76: https://ieeexplore.ieee.org/document/9787844 | C76: ieee | D76: ------------- | E76: Technology Agnostic - TA | F76: Multi (for TA) | G76: 5- Performance & Resource management, 5-1- Resource Optimization, 5-3- Lifecycle management, 1- Structural Quality | H76: Implementation | I76: Project | J76: Other | K76: Tests | L76: 5 - Testing & Excution based | M76: Dynamic | N76: Yes | O76: https://github.com/cannavit/smoke-test.git | P76: RankA | Q76: 2022 | R76: WhiteBox | S76: Code access | T76: Github
A77: Source code properties of defective infrastructure as code scripts | B77: https://dl.acm.org/doi/10.1016/j.infsof.2019.04.013 | C77: science direct (done) | D77: ------------- | E77: Technology Dependent - TD | F77: Puppet | G77: 1- Structural Quality, 1-3- Code structure, 6- Maintability & Documentation, 6-1- Code Readability, 7- Data & Variable management, 7-2- Vraibale management | H77: Design | I77: Script | J77: Config management | K77: Configuration mining, Statistical Learners | L77: 4 - Statistical and Learning-Based Methods | M77: NA | N77: No | O77: https://figshare.com/s/ad26e370c833e8aa9712 | Q77: 2019 | R77: NA | S77: Dataset | T77: Figshare
A78: Security Misconfigurations in Open Source Kubernetes Manifests: An Empirical Study | B78: https://dl.acm.org/doi/10.1145/3579639 | C78: acm (done) | D78: SLI-KUBE | E78: Technology Dependent - TD | F78: Kubernetes | G78: 3- Security, 3-1- Authentication & Authorization, 3-2- Secrets Management, 3-3- Network Security, 9- Domain Specific Issues, 9-1- Container & Orchestration | H78: Design | I78: Script | J78: Orchestration | K78: Rule-based checks | L78: 1 - Rule-Based and Pattern-Matching Approaches | M78: Static | N78: Yes | O78: https://figshare.com/s/bced7c8353853a983cd7 | Q78: 2023 | R78: WhiteBox | S78: Both | T78: Figshare
...

Sheet Visualizations2
A1: =IFERROR(__xludf.DUMMYFUNCTION("UNIQUE(ARRAYFORMULA(TRIM(FLATTEN(SPLIT(TEXTJOIN("","", TRUE, 'Final set of papers'!E2:E1000), "","")))))"),"Technology Specifi - TS") -> Technology Specifi - TS | B1: =COUNTIF('Final set of papers'!E2:E1000, "*" & A1 & "*") -> 42 | D1: =IFERROR(__xludf.DUMMYFUNCTION("SORT(UNIQUE(ARRAYFORMULA(TRIM(FLATTEN(SPLIT(TEXTJOIN("","", TRUE, 'Final set of papers'!G2:G1000), "",""))))))"),"1- Structural Quality") -> 1- Structural Quality | E1: =COUNTIF('Final set of papers'!G2:G1000, "*" & D1 & "*") -> 19 | G1: =IFERROR(__xludf.DUMMYFUNCTION("SORT(UNIQUE(ARRAYFORMULA(TRIM(FLATTEN(SPLIT(TEXTJOIN("","", TRUE, 'Final set of papers'!K2:K1000), "",""))))))"),"AST traversal") -> AST traversal | H1: =COUNTIF('Final set of papers'!K2:K1000, "*" & G1 & "*") -> 6 | J1: 1 - Rule-Based and Pattern-Matching Approaches | N1: =IFERROR(__xludf.DUMMYFUNCTION("SORT(UNIQUE(ARRAYFORMULA(TRIM(FLATTEN(SPLIT(TEXTJOIN("","", TRUE, 'Final set of papers'!Q2:Q1000), "",""))))))"),"2015") -> 2015 | O1: =COUNTIF('Final set of papers'!Q2:Q1000, N1) -> 1
A2: =IFERROR(__xludf.DUMMYFUNCTION("""COMPUTED_VALUE"""),"Technology Agnostic - TA") -> Technology Agnostic - TA | B2: =COUNTIF('Final set of papers'!E2:E1000, "*" & A2 & "*") -> 10 | D2: =IFERROR(__xludf.DUMMYFUNCTION("""COMPUTED_VALUE"""),"1-1- Abstraction issues") -> 1-1- Abstraction issues | E2: =COUNTIF('Final set of papers'!G2:G1000, "*" & D2 & "*") -> 3 | G2: =IFERROR(__xludf.DUMMYFUNCTION("""COMPUTED_VALUE"""),"Configuration mining") -> Configuration mining | H2: =COUNTIF('Final set of papers'!K2:K1000, "*" & G2 & "*") -> 3 | J2: Regular Expressions - RegX | N2: =IFERROR(__xludf.DUMMYFUNCTION("""COMPUTED_VALUE"""),"2016") -> 2016 | O2: =COUNTIF('Final set of papers'!Q2:Q1000, N2) -> 2
A3: =IFERROR(__xludf.DUMMYFUNCTION("""COMPUTED_VALUE"""),"Technology Dependent - TD") -> Technology Dependent - TD | B3: =COUNTIF('Final set of papers'!E3:E1000, "*" & A3 & "*") -> 13 | D3: =IFERROR(__xludf.DUMMYFUNCTION("""COMPUTED_VALUE"""),"1-2- Modularity & Organization") -> 1-2- Modularity & Organization | E3: =COUNTIF('Final set of papers'!G2:G1000, "*" & D3 & "*") -> 8 | G3: =IFERROR(__xludf.DUMMYFUNCTION("""COMPUTED_VALUE"""),"Control Flow Graph") -> Control Flow Graph | H3: =COUNTIF('Final set of papers'!K2:K1000, "*" & G3 & "*") -> 1 | J3: Rule-based checks | N3: =IFERROR(__xludf.DUMMYFUNCTION("""COMPUTED_VALUE"""),"2017") -> 2017 | O3: =COUNTIF('Final set of papers'!Q2:Q1000, N3) -> 1
D4: =IFERROR(__xludf.DUMMYFUNCTION("""COMPUTED_VALUE"""),"1-3- Code structure") -> 1-3- Code structure | E4: =COUNTIF('Final set of papers'!G2:G1000, "*" & D4 & "*") -> 12 | G4: =IFERROR(__xludf.DUMMYFUNCTION("""COMPUTED_VALUE"""),"Data Dependecy Graph - DDG") -> Data Dependecy Graph - DDG | H4: =COUNTIF('Final set of papers'!K5:K1000, "*" & G4 & "*") -> 3 | J4: Pattern Matching | N4: =IFERROR(__xludf.DUMMYFUNCTION("""COMPUTED_VALUE"""),"2018") -> 2018 | O4: =COUNTIF('Final set of papers'!Q2:Q1000, N4) -> 2
D5: =IFERROR(__xludf.DUMMYFUNCTION("""COMPUTED_VALUE"""),"2- Syntactic & Linguistic Quality") -> 2- Syntactic & Linguistic Quality | E5: =COUNTIF('Final set of papers'!G2:G1000, "*" & D5 & "*") -> 19 | G5: =IFERROR(__xludf.DUMMYFUNCTION("""COMPUTED_VALUE"""),"Deep Learning - DL") -> Deep Learning - DL | H5: =COUNTIF('Final set of papers'!K2:K1000, "*" & G5 & "*") -> 2 | J5: Pattern Algorithms | N5: =IFERROR(__xludf.DUMMYFUNCTION("""COMPUTED_VALUE"""),"2019") -> 2019 | O5: =COUNTIF('Final set of papers'!Q2:Q1000, N5) -> 3
A6: =IFERROR(__xludf.DUMMYFUNCTION("UNIQUE(ARRAYFORMULA(TRIM(FLATTEN(SPLIT(TEXTJOIN("","", TRUE, 'Final set of papers'!F2:F1000), "","")))))"),"Puppet") -> Puppet | B6: =IFERROR(__xludf.DUMMYFUNCTION("COUNTIF(FLATTEN(ARRAYFORMULA(TRIM(SPLIT('Final set of papers'!F2:F1000, "","")))),A6)"),14.0) -> 14 | D6: =IFERROR(__xludf.DUMMYFUNCTION("""COMPUTED_VALUE"""),"2-1- Naming & conventions") -> 2-1- Naming & conventions | E6: =COUNTIF('Final set of papers'!G2:G1000, "*" & D6 & "*") -> 5 | G6: =IFERROR(__xludf.DUMMYFUNCTION("""COMPUTED_VALUE"""),"LLMs") -> LLMs | H6: =COUNTIF('Final set of papers'!K7:K1000, "*" & G6 & "*") -> 6 | J6: Visitor Pattern | N6: =IFERROR(__xludf.DUMMYFUNCTION("""COMPUTED_VALUE"""),"2020") -> 2020 | O6: =COUNTIF('Final set of papers'!Q2:Q1000, N6) -> 5
A7: =IFERROR(__xludf.DUMMYFUNCTION("""COMPUTED_VALUE"""),"Ansible") -> Ansible | B7: =IFERROR(__xludf.DUMMYFUNCTION("COUNTIF(FLATTEN(ARRAYFORMULA(TRIM(SPLIT('Final set of papers'!F2:F1000, "","")))),A7)"),16.0) -> 16 | D7: =IFERROR(__xludf.DUMMYFUNCTION("""COMPUTED_VALUE"""),"2-2- Syntax & Formatting") -> 2-2- Syntax & Formatting | E7: =COUNTIF('Final set of papers'!G2:G1000, "*" & D7 & "*") -> 7 | G7: =IFERROR(__xludf.DUMMYFUNCTION("""COMPUTED_VALUE"""),"Machine Learning - ML") -> Machine Learning - ML | H7: =COUNTIF('Final set of papers'!K8:K1000, "*" & G7 & "*") -> 3 | J7: 2 - Graph-Based Analyses | N7: =IFERROR(__xludf.DUMMYFUNCTION("""COMPUTED_VALUE"""),"2021") -> 2021 | O7: =COUNTIF('Final set of papers'!Q2:Q1000, N7) -> 1
A8: =IFERROR(__xludf.DUMMYFUNCTION("""COMPUTED_VALUE"""),"Multi (for TA)") -> Multi (for TA) | B8: =COUNTIF('Final set of papers'!F2:F1000, "*" & A8 & "*") -> 6 | D8: =IFERROR(__xludf.DUMMYFUNCTION("""COMPUTED_VALUE"""),"2-3- Language constructs") -> 2-3- Language constructs | E8: =COUNTIF('Final set of papers'!G2:G1000, "*" & D8 & "*") -> 8 | G8: =IFERROR(__xludf.DUMMYFUNCTION("""COMPUTED_VALUE"""),"Manual annotation") -> Manual annotation | H8: =COUNTIF('Final set of papers'!K9:K1000, "*" & G8 & "*") -> 2 | J8: AST Traversal | N8: =IFERROR(__xludf.DUMMYFUNCTION("""COMPUTED_VALUE"""),"2022") -> 2022 | O8: =COUNTIF('Final set of papers'!Q2:Q1000, N8) -> 8
A9: =IFERROR(__xludf.DUMMYFUNCTION("""COMPUTED_VALUE"""),"Terraform") -> Terraform | B9: =IFERROR(__xludf.DUMMYFUNCTION("COUNTIF(FLATTEN(ARRAYFORMULA(TRIM(SPLIT('Final set of papers'!F2:F1000, "","")))),A9)"),9.0) -> 9 | D9: =IFERROR(__xludf.DUMMYFUNCTION("""COMPUTED_VALUE"""),"3- Security") -> 3- Security | E9: =COUNTIF('Final set of papers'!G2:G1000, "*" & D9 & "*") -> 33 | G9: =IFERROR(__xludf.DUMMYFUNCTION("""COMPUTED_VALUE"""),"NA") -> NA | H9: =COUNTIF('Final set of papers'!K10:K1000, "*" & G9 & "*") -> 7 | J9: Control Flow Graph | N9: =IFERROR(__xludf.DUMMYFUNCTION("""COMPUTED_VALUE"""),"2023") -> 2023 | O9: =COUNTIF('Final set of papers'!Q2:Q1000, N9) -> 17
A10: =IFERROR(__xludf.DUMMYFUNCTION("""COMPUTED_VALUE"""),"Chef") -> Chef | B10: =COUNTIF('Final set of papers'!F2:F1000, "*" & A10 & "*") -> 3 | D10: =IFERROR(__xludf.DUMMYFUNCTION("""COMPUTED_VALUE"""),"3-1- Authentication & Authorization") -> 3-1- Authentication & Authorization | E10: =COUNTIF('Final set of papers'!G11:G1000, "*" & D10 & "*") -> 12 | G10: =IFERROR(__xludf.DUMMYFUNCTION("""COMPUTED_VALUE"""),"NLP") -> NLP | H10: =COUNTIF('Final set of papers'!K11:K1000, "*" & G10 & "*") -> 1 | J10: Data Dependecy Graph - DDG | N10: =IFERROR(__xludf.DUMMYFUNCTION("""COMPUTED_VALUE"""),"2024") -> 2024 | O10: =COUNTIF('Final set of papers'!Q2:Q1000, N10) -> 17
A11: =IFERROR(__xludf.DUMMYFUNCTION("""COMPUTED_VALUE"""),"TOSCA") -> TOSCA | B11: =COUNTIF('Final set of papers'!F2:F1000, "*" & A11 & "*") -> 2 | D11: =IFERROR(__xludf.DUMMYFUNCTION("""COMPUTED_VALUE"""),"3-2- Secrets Management") -> 3-2- Secrets Management | E11: =COUNTIF('Final set of papers'!G12:G1000, "*" & D11 & "*") -> 13 | G11: =IFERROR(__xludf.DUMMYFUNCTION("""COMPUTED_VALUE"""),"Other") -> Other | H11: =COUNTIF('Final set of papers'!K2:K1000, "*" & G11 & "*") -> 7 | J11: Program Dependncy Graph - PDG | N11: =IFERROR(__xludf.DUMMYFUNCTION("""COMPUTED_VALUE"""),"2025") -> 2025 | O11: =COUNTIF('Final set of papers'!Q2:Q1000, N11) -> 8
A12: =IFERROR(__xludf.DUMMYFUNCTION("""COMPUTED_VALUE"""),"Cloud Formation") -> Cloud Formation | B12: =COUNTIF('Final set of papers'!F2:F1000, "*" & A12 & "*") -> 3 | D12: =IFERROR(__xludf.DUMMYFUNCTION("""COMPUTED_VALUE"""),"3-3- Network Security") -> 3-3- Network Security | E12: =COUNTIF('Final set of papers'!G13:G1000, "*" & D12 & "*") -> 13 | G12: =IFERROR(__xludf.DUMMYFUNCTION("""COMPUTED_VALUE"""),"Pattern Algorithms") -> Pattern Algorithms | H12: =COUNTIF('Final set of papers'!K2:K1000, "*" & G12 & "*") -> 1 | J12: Resource Graph - RG
A13: =IFERROR(__xludf.DUMMYFUNCTION("""COMPUTED_VALUE"""),"Kubernetes") -> Kubernetes | B13: =COUNTIF('Final set of papers'!F2:F1000, "*" & A13 & "*") -> 7 | D13: =IFERROR(__xludf.DUMMYFUNCTION("""COMPUTED_VALUE"""),"3-4- Cryptography & Integrity") -> 3-4- Cryptography & Integrity | E13: =COUNTIF('Final set of papers'!G14:G1000, "*" & D13 & "*") -> 9 | G13: =IFERROR(__xludf.DUMMYFUNCTION("""COMPUTED_VALUE"""),"Pattern Matching") -> Pattern Matching | H13: =COUNTIF('Final set of papers'!K2:K1000, "*" & G13 & "*") -> 8 | J13: 3 - Formal Methods
A14: =IFERROR(__xludf.DUMMYFUNCTION("""COMPUTED_VALUE"""),"Pulumi") -> Pulumi | B14: =COUNTIF('Final set of papers'!F2:F1000, "*" & A14 & "*") -> 5 | D14: =IFERROR(__xludf.DUMMYFUNCTION("""COMPUTED_VALUE"""),"4- Operational Quality") -> 4- Operational Quality | E14: =COUNTIF('Final set of papers'!G2:G1000, "*" & D14 & "*") -> 24 | G14: =IFERROR(__xludf.DUMMYFUNCTION("""COMPUTED_VALUE"""),"Program Dependncy Graph - PDG") -> Program Dependncy Graph - PDG | H14: =COUNTIF('Final set of papers'!K2:K1000, "*" & G14 & "*") -> 4 | J14: SMT solvers | N14: 1- Structural Quality | O14: 19
A15: =IFERROR(__xludf.DUMMYFUNCTION("""COMPUTED_VALUE"""),"Docker-compose") -> Docker-compose | B15: =COUNTIF('Final set of papers'!F2:F1000, "*" & A15 & "*") -> 1 | D15: =IFERROR(__xludf.DUMMYFUNCTION("""COMPUTED_VALUE"""),"4-1- Idempotency & State management") -> 4-1- Idempotency & State management | E15: =COUNTIF('Final set of papers'!G16:G1000, "*" & D15 & "*") -> 8 | G15: =IFERROR(__xludf.DUMMYFUNCTION("""COMPUTED_VALUE"""),"RAG") -> RAG | H15: =COUNTIF('Final set of papers'!K16:K1000, "*" & G15 & "*") -> 1 | J15: 4 - Statistical and Learning-Based Methods | N15: 2- Syntactic & Linguistic Quality | O15: 19
A16: =IFERROR(__xludf.DUMMYFUNCTION("""COMPUTED_VALUE"""),"Docker") -> Docker | B16: =IFERROR(__xludf.DUMMYFUNCTION("COUNTIF(FLATTEN(ARRAYFORMULA(TRIM(SPLIT('Final set of papers'!F2:F1000, "","")))),A16)"),7.0) -> 7 | D16: =IFERROR(__xludf.DUMMYFUNCTION("""COMPUTED_VALUE"""),"4-2- Error Handling & Reliability") -> 4-2- Error Handling & Reliability | E16: =COUNTIF('Final set of papers'!G17:G1000, "*" & D16 & "*") -> 8 | G16: =IFERROR(__xludf.DUMMYFUNCTION("""COMPUTED_VALUE"""),"Regular Expressions - RegX") -> Regular Expressions - RegX | H16: =COUNTIF('Final set of papers'!K2:K1000, "*" & J2 & "*") -> 7 | J16: Machine Learning - ML | N16: 3- Security | O16: 33
A17: =IFERROR(__xludf.DUMMYFUNCTION("""COMPUTED_VALUE"""),"Helm") -> Helm | B17: =COUNTIF('Final set of papers'!F2:F1000, "*" & A17 & "*") -> 1 | D17: =IFERROR(__xludf.DUMMYFUNCTION("""COMPUTED_VALUE"""),"4-3- Dependecies & integration") -> 4-3- Dependecies & integration | E17: =COUNTIF('Final set of papers'!G18:G1000, "*" & D17 & "*") -> 8 | G17: =IFERROR(__xludf.DUMMYFUNCTION("""COMPUTED_VALUE"""),"Resource Graph - RG") -> Resource Graph - RG | H17: =COUNTIF('Final set of papers'!K2:K1000, "*" & G17 & "*") -> 5 | J17: Statistical Learners | N17: 4- Operational Quality | O17: 24
D18: =IFERROR(__xludf.DUMMYFUNCTION("""COMPUTED_VALUE"""),"5- Performance & Resource management") -> 5- Performance & Resource management | E18: =COUNTIF('Final set of papers'!G2:G1000, "*" & D18 & "*") -> 11 | G18: =IFERROR(__xludf.DUMMYFUNCTION("""COMPUTED_VALUE"""),"Rewriting / Refactoring") -> Rewriting / Refactoring | H18: =COUNTIF('Final set of papers'!K2:K1000, "*" & G18 & "*") -> 1 | J18: Deep Learning - DL | N18: 5- Performance & Resource management | O18: 11
D19: =IFERROR(__xludf.DUMMYFUNCTION("""COMPUTED_VALUE"""),"5-1- Resource Optimization") -> 5-1- Resource Optimization | E19: =COUNTIF('Final set of papers'!G20:G1000, "*" & D19 & "*") -> 5 | G19: =IFERROR(__xludf.DUMMYFUNCTION("""COMPUTED_VALUE"""),"Rule-based checks") -> Rule-based checks | H19: =COUNTIF('Final set of papers'!K2:K1000, "*" & G19 & "*") -> 6 | J19: LLMs | N19: 6- Maintability & Documentation | O19: 16
A20: =IFERROR(__xludf.DUMMYFUNCTION("UNIQUE(ARRAYFORMULA(TRIM(FLATTEN(SPLIT(TEXTJOIN("","", TRUE, 'Final set of papers'!H2:H1000), "","")))))"),"Implementation") -> Implementation | B20: =COUNTIF('Final set of papers'!H2:H1000, "*" & A20 & "*") -> 55 | D20: =IFERROR(__xludf.DUMMYFUNCTION("""COMPUTED_VALUE"""),"5-2- Scalability") -> 5-2- Scalability | E20: =COUNTIF('Final set of papers'!G21:G1000, "*" & D20 & "*") -> 1 | G20: =IFERROR(__xludf.DUMMYFUNCTION("""COMPUTED_VALUE"""),"SMT solvers") -> SMT solvers | H20: =COUNTIF('Final set of papers'!K21:K1000, "*" & G20 & "*") -> 4 | J20: RAG | N20: 7- Data & Variable management | O20: 16
A21: =IFERROR(__xludf.DUMMYFUNCTION("""COMPUTED_VALUE"""),"Design") -> Design | B21: =COUNTIF('Final set of papers'!H2:H1000, "*" & A21 & "*") -> 9 | D21: =IFERROR(__xludf.DUMMYFUNCTION("""COMPUTED_VALUE"""),"5-3- Lifecycle management") -> 5-3- Lifecycle management | E21: =COUNTIF('Final set of papers'!G22:G1000, "*" & D21 & "*") -> 4 | G21: =IFERROR(__xludf.DUMMYFUNCTION("""COMPUTED_VALUE"""),"Statistical Learners") -> Statistical Learners | H21: =COUNTIF('Final set of papers'!K2:K1000, "*" & G21 & "*") -> 4 | J21: NLP | N21: 8- Control Flow & Logic | O21: 11
A22: =IFERROR(__xludf.DUMMYFUNCTION("""COMPUTED_VALUE"""),"Runtime") -> Runtime | B22: =COUNTIF('Final set of papers'!H2:H1000, "*" & A22 & "*") -> 10 | D22: =IFERROR(__xludf.DUMMYFUNCTION("""COMPUTED_VALUE"""),"6- Maintability & Documentation") -> 6- Maintability & Documentation | E22: =COUNTIF('Final set of papers'!G2:G1000, "*" & D22 & "*") -> 16 | G22: =IFERROR(__xludf.DUMMYFUNCTION("""COMPUTED_VALUE"""),"Tests") -> Tests | H22: =COUNTIF('Final set of papers'!K23:K1000, "*" & G22 & "*") -> 5 | J22: 5 - Testing Methods | N22: 9- Domain Specific Issues | O22: 10
D23: =IFERROR(__xludf.DUMMYFUNCTION("""COMPUTED_VALUE"""),"6-1- Code Readability") -> 6-1- Code Readability | E23: =COUNTIF('Final set of papers'!G24:G1000, "*" & D23 & "*") -> 4 | G23: =IFERROR(__xludf.DUMMYFUNCTION("""COMPUTED_VALUE"""),"Visitor Pattern") -> Visitor Pattern | H23: =COUNTIF('Final set of papers'!K2:K1000, "*" & G23 & "*") -> 2 | J23: Tests
A24: =IFERROR(__xludf.DUMMYFUNCTION("UNIQUE(ARRAYFORMULA(TRIM(FLATTEN(SPLIT(TEXTJOIN("","", TRUE, 'Final set of papers'!I2:I1000), "","")))))"),"Script") -> Script | B24: =COUNTIF('Final set of papers'!I2:I1000, "*" & A24 & "*") -> 50 | D24: =IFERROR(__xludf.DUMMYFUNCTION("""COMPUTED_VALUE"""),"6-2- Version control & Compatibility") -> 6-2- Version control & Compatibility | E24: =COUNTIF('Final set of papers'!G25:G1000, "*" & D24 & "*") -> 3
A25: =IFERROR(__xludf.DUMMYFUNCTION("""COMPUTED_VALUE"""),"Module") -> Module | B25: =COUNTIF('Final set of papers'!I2:I1000, "*" & A25 & "*") -> 6 | D25: =IFERROR(__xludf.DUMMYFUNCTION("""COMPUTED_VALUE"""),"6-3- Code Reusability") -> 6-3- Code Reusability | E25: =COUNTIF('Final set of papers'!G26:G1000, "*" & D25 & "*") -> 1
A26: =IFERROR(__xludf.DUMMYFUNCTION("""COMPUTED_VALUE"""),"Project") -> Project | B26: =COUNTIF('Final set of papers'!I4:I1000, "*" & A26 & "*") -> 12 | D26: =IFERROR(__xludf.DUMMYFUNCTION("""COMPUTED_VALUE"""),"7- Data & Variable management") -> 7- Data & Variable management | E26: =COUNTIF('Final set of papers'!G2:G1000, "*" & D26 & "*") -> 16 | G26: =IFERROR(__xludf.DUMMYFUNCTION("SORT(UNIQUE(ARRAYFORMULA(TRIM(FLATTEN(SPLIT(TEXTJOIN("","", TRUE, #REF!), "",""))))))"),"#REF!") -> #REF! | H26: =COUNTIF(#REF!, "*" & G26 & "*") -> 1 | J26: =IFERROR(__xludf.DUMMYFUNCTION("SORT(UNIQUE(ARRAYFORMULA(TRIM(FLATTEN(SPLIT(TEXTJOIN("","", TRUE, 'Final set of papers'!L2:L1000), "",""))))))"),"1 - Rule-Based and Pattern-Matching Approaches") -> 1 - Rule-Based and Pattern-Matching Approaches | K26: =COUNTIF('Final set of papers'!L2:L1000, "*" & J26 & "*") -> 23 | N26: =IFERROR(__xludf.DUMMYFUNCTION("UNIQUE(ARRAYFORMULA(TRIM(FLATTEN(SPLIT(TEXTJOIN("","", TRUE, 'Final set of papers'!S2:S1000), "","")))))"),"Both") -> Both | O26: =COUNTIF('Final set of papers'!S2:S1000, "*" & N26 & "*") -> 34
D27: =IFERROR(__xludf.DUMMYFUNCTION("""COMPUTED_VALUE"""),"7-1- Configuration Data") -> 7-1- Configuration Data | E27: =COUNTIF('Final set of papers'!G28:G1000, "*" & D27 & "*") -> 2 | H27: =COUNTIF(#REF!, "*" & G27 & "*") -> 0 | J27: =IFERROR(__xludf.DUMMYFUNCTION("""COMPUTED_VALUE"""),"2 - Graph-Based Analyses") -> 2 - Graph-Based Analyses | K27: =COUNTIF('Final set of papers'!L2:L1000, "*" & J27 & "*") -> 19 | N27: =IFERROR(__xludf.DUMMYFUNCTION("""COMPUTED_VALUE"""),"Code access") -> Code access | O27: =COUNTIF('Final set of papers'!S2:S1000, "*" & N27 & "*") -> 8
D28: =IFERROR(__xludf.DUMMYFUNCTION("""COMPUTED_VALUE"""),"7-2- Vraibale management") -> 7-2- Vraibale management | E28: =COUNTIF('Final set of papers'!G29:G1000, "*" & D28 & "*") -> 2 | H28: =COUNTIF(#REF!, "*" & G28 & "*") -> 0 | J28: =IFERROR(__xludf.DUMMYFUNCTION("""COMPUTED_VALUE"""),"3 - Formal Methods") -> 3 - Formal Methods | K28: =COUNTIF('Final set of papers'!L2:L1000, "*" & J28 & "*") -> 5 | N28: =IFERROR(__xludf.DUMMYFUNCTION("""COMPUTED_VALUE"""),"Dataset") -> Dataset | O28: =COUNTIF('Final set of papers'!S2:S1000, "*" & N28 & "*") -> 9
D29: =IFERROR(__xludf.DUMMYFUNCTION("""COMPUTED_VALUE"""),"8- Control Flow & Logic") -> 8- Control Flow & Logic | E29: =COUNTIF('Final set of papers'!G2:G1000, "*" & D29 & "*") -> 11 | H29: =COUNTIF(#REF!, "*" & G29 & "*") -> 0 | J29: =IFERROR(__xludf.DUMMYFUNCTION("""COMPUTED_VALUE"""),"4 - Statistical and Learning-Based Methods") -> 4 - Statistical and Learning-Based Methods | K29: =COUNTIF('Final set of papers'!L2:L1000, "*" & J29 & "*") -> 19 | N29: =IFERROR(__xludf.DUMMYFUNCTION("""COMPUTED_VALUE"""),"Not available") -> Not available | O29: =COUNTIF('Final set of papers'!S2:S1000, "*" & N29 & "*") -> 14
A30: =IFERROR(__xludf.DUMMYFUNCTION("UNIQUE(ARRAYFORMULA(TRIM(FLATTEN(SPLIT(TEXTJOIN("","", TRUE, 'Final set of papers'!J2:J1000), "","")))))"),"Config management") -> Config management | B30: =COUNTIF('Final set of papers'!J2:J1000, "*" & A30 & "*") -> 30 | D30: =IFERROR(__xludf.DUMMYFUNCTION("""COMPUTED_VALUE"""),"8-1- Program Flow") -> 8-1- Program Flow | E30: =COUNTIF('Final set of papers'!G31:G1000, "*" & D30 & "*") -> 0 | H30: =COUNTIF(#REF!, "*" & G30 & "*") -> 0 | J30: =IFERROR(__xludf.DUMMYFUNCTION("""COMPUTED_VALUE"""),"5 - Testing & Excution based") -> 5 - Testing & Excution based | K30: =COUNTIF('Final set of papers'!L2:L1000, "*" & J30 & "*") -> 7
A31: =IFERROR(__xludf.DUMMYFUNCTION("""COMPUTED_VALUE"""),"Other") -> Other | B31: =COUNTIF('Final set of papers'!J2:J1000, "*" & A31 & "*") -> 7 | D31: =IFERROR(__xludf.DUMMYFUNCTION("""COMPUTED_VALUE"""),"8-2- Function & Method Logic") -> 8-2- Function & Method Logic | E31: =COUNTIF('Final set of papers'!G32:G1000, "*" & D31 & "*") -> 1 | H31: =COUNTIF(#REF!, "*" & G31 & "*") -> 0 | J31: =IFERROR(__xludf.DUMMYFUNCTION("""COMPUTED_VALUE"""),"6 - Other") -> 6 - Other | K31: =COUNTIF('Final set of papers'!L2:L1000, "*" & J31 & "*") -> 8
A32: =IFERROR(__xludf.DUMMYFUNCTION("""COMPUTED_VALUE"""),"Provisioning") -> Provisioning | B32: =COUNTIF('Final set of papers'!J2:J1000, "*" & A32 & "*") -> 16 | D32: =IFERROR(__xludf.DUMMYFUNCTION("""COMPUTED_VALUE"""),"9- Domain Specific Issues") -> 9- Domain Specific Issues | E32: =COUNTIF('Final set of papers'!G2:G1000, "*" & D32 & "*") -> 10 | J32: =IFERROR(__xludf.DUMMYFUNCTION("""COMPUTED_VALUE"""),"NA") -> NA | K32: =COUNTIF('Final set of papers'!L2:L1000, J32) -> 6 | N32: =IFERROR(__xludf.DUMMYFUNCTION("UNIQUE(ARRAYFORMULA(TRIM(FLATTEN(SPLIT(TEXTJOIN("","", TRUE, 'Final set of papers'!T2:T1000), "","")))))"),"Github") -> Github | O32: =COUNTIF('Final set of papers'!T2:T1000, "*" & N32 & "*") -> 27 | Q32: Github | R32: 27
A33: =IFERROR(__xludf.DUMMYFUNCTION("""COMPUTED_VALUE"""),"Orchestration") -> Orchestration | B33: =COUNTIF('Final set of papers'!J2:J1000, "*" & A33 & "*") -> 8 | D33: =IFERROR(__xludf.DUMMYFUNCTION("""COMPUTED_VALUE"""),"9-1- Container & Orchestration") -> 9-1- Container & Orchestration | E33: =COUNTIF('Final set of papers'!G34:G1000, "*" & D33 & "*") -> 2 | N33: =IFERROR(__xludf.DUMMYFUNCTION("""COMPUTED_VALUE"""),"Figshare") -> Figshare | O33: =COUNTIF('Final set of papers'!T2:T1000, "*" & N33 & "*") -> 18 | Q33: Figshare | R33: 18
A34: =IFERROR(__xludf.DUMMYFUNCTION("""COMPUTED_VALUE"""),"Image building") -> Image building | B34: =COUNTIF('Final set of papers'!J2:J1000, "*" & A34 & "*") -> 7 | D34: =IFERROR(__xludf.DUMMYFUNCTION("""COMPUTED_VALUE"""),"9-2- Cloud Provider Specfic") -> 9-2- Cloud Provider Specfic | E34: =COUNTIF('Final set of papers'!G35:G1000, "*" & D34 & "*") -> 1 | N34: =IFERROR(__xludf.DUMMYFUNCTION("""COMPUTED_VALUE"""),"Docker hub") -> Docker hub | O34: =COUNTIF('Final set of papers'!T2:T1000, "*" & N34 & "*") -> 2 | Q34: Docker hub | R34: 2
D35: =IFERROR(__xludf.DUMMYFUNCTION("""COMPUTED_VALUE"""),"9-3- Infra components") -> 9-3- Infra components | E35: =COUNTIF('Final set of papers'!G36:G1000, "*" & D35 & "*") -> 2 | N35: =IFERROR(__xludf.DUMMYFUNCTION("""COMPUTED_VALUE"""),"NA") -> NA | O35: =COUNTIF('Final set of papers'!T5:T1000, "*" & N35 & "*") -> 14 | Q35: Zenodo | R35: 12
D36: =IFERROR(__xludf.DUMMYFUNCTION("""COMPUTED_VALUE"""),"NA") -> NA | E36: =COUNTIF('Final set of papers'!G37:G1000,D36) -> 1 | N36: =IFERROR(__xludf.DUMMYFUNCTION("""COMPUTED_VALUE"""),"Zenodo") -> Zenodo | O36: =COUNTIF('Final set of papers'!T2:T1000, "*" & N36 & "*") -> 12 | Q36: Kaggle | R36: 1
N37: =IFERROR(__xludf.DUMMYFUNCTION("""COMPUTED_VALUE"""),"Kaggle") -> Kaggle | O37: =COUNTIF('Final set of papers'!T2:T1000, "*" & N37 & "*") -> 1
A38: =IFERROR(__xludf.DUMMYFUNCTION("UNIQUE(ARRAYFORMULA(TRIM(FLATTEN(SPLIT(TEXTJOIN("","", TRUE, 'Final set of papers'!N2:N1000), "","")))))"),"Yes") -> Yes | B38: =COUNTIF('Final set of papers'!N2:N1000, "*" & A38 & "*") -> 57
A39: =IFERROR(__xludf.DUMMYFUNCTION("""COMPUTED_VALUE"""),"No") -> No | B39: =COUNTIF('Final set of papers'!N2:N1000, "*" & A39 & "*") -> 8 | G39: =IFERROR(__xludf.DUMMYFUNCTION("SORT(UNIQUE(ARRAYFORMULA(TRIM(FLATTEN(SPLIT(TEXTJOIN("","", TRUE, 'Final set of papers'!M2:M1000), "",""))))))"),"Dynamic") -> Dynamic | H39: =COUNTIF('Final set of papers'!M2:M1000, "*" & G39 & "*") -> 6
G40: =IFERROR(__xludf.DUMMYFUNCTION("""COMPUTED_VALUE"""),"Hybrid") -> Hybrid | H40: =COUNTIF('Final set of papers'!M3:M1000, "*" & G40 & "*") -> 4
...

Sheet IaC_issues_across_platforms
A1: Column 1 | B1: 1- Structural Quality | C1: 2- Syntactic & Linguistic Quality | D1: 3- Security | E1: 4- Operational Quality | F1: 5- Performance & Resource management | G1: 6- Maintability & Documentation | H1: 7- Data & Variable management | I1: 8- Control Flow & Logic | J1: 9- Domain Specific Issues
A2: =IFERROR(__xludf.DUMMYFUNCTION("UNIQUE(ARRAYFORMULA(TRIM(FLATTEN(SPLIT(TEXTJOIN("","", TRUE, 'Final set of papers'!F2:F1000), "","")))))"),"Puppet") -> Puppet | B2: =COUNTIFS( 'Final set of papers'!$F$2:$F1000, "*"&A2&"*", 'Final set of papers'!$G$2:$G1000, "*"&Table1[[#HEADERS],[1- Structural Quality]]&"*" ) -> 4 | C2: =COUNTIFS( 'Final set of papers'!$F$2:$F1000, "*"&A2&"*", 'Final set of papers'!$G$2:$G1000, "*"&Table1[[#HEADERS],[2- Syntactic & Linguistic Quality]]&"*" ) -> 3 | D2: =COUNTIFS( 'Final set of papers'!$F$2:$F1000, "*"&A2&"*", 'Final set of papers'!$G$2:$G1000, "*"&Table1[[#HEADERS],[3- Security]]&"*" ) -> 5 | E2: =COUNTIFS( 'Final set of papers'!$F$2:$F1000, "*"&A2&"*", 'Final set of papers'!$G$2:$G1000, "*"&Table1[[#HEADERS],[4- Operational Quality]]&"*" ) -> 3 | F2: =COUNTIFS( 'Final set of papers'!$F$2:$F1000, "*"&A2&"*", 'Final set of papers'!$G$2:$G1000, "*"&Table1[[#HEADERS],[5- Performance & Resource management]]&"*" ) -> 0 | G2: =COUNTIFS( 'Final set of papers'!$F$2:$F1000, "*"&A2&"*", 'Final set of papers'!$G$2:$G1000, "*"&Table1[[#HEADERS],[6- Maintability & Documentation]]&"*" ) -> 4 | H2: =COUNTIFS( 'Final set of papers'!$F$2:$F1000, "*"&A2&"*", 'Final set of papers'!$G$2:$G1000, "*"&Table1[[#HEADERS],[7- Data & Variable management]]&"*" ) -> 2 | I2: =COUNTIFS( 'Final set of papers'!$F$2:$F1000, "*"&A2&"*", 'Final set of papers'!$G$2:$G1000, "*"&Table1[[#HEADERS],[8- Control Flow & Logic]]&"*" ) -> 2 | J2: =COUNTIFS( 'Final set of papers'!$F$2:$F1000, "*"&A2&"*", 'Final set of papers'!$G$2:$G1000, "*"&Table1[[#HEADERS],[9- Domain Specific Issues]]&"*" ) -> 1
A3: =IFERROR(__xludf.DUMMYFUNCTION("""COMPUTED_VALUE"""),"Ansible") -> Ansible | B3: =COUNTIFS( 'Final set of papers'!$F$2:$F1000, "*"&A3&"*", 'Final set of papers'!$G$2:$G1000, "*"&Table1[[#HEADERS],[1- Structural Quality]]&"*" ) -> 6 | C3: =COUNTIFS( 'Final set of papers'!$F$2:$F1000, "*"&A3&"*", 'Final set of papers'!$G$2:$G1000, "*"&Table1[[#HEADERS],[2- Syntactic & Linguistic Quality]]&"*" ) -> 9 | D3: =COUNTIFS( 'Final set of papers'!$F$2:$F1000, "*"&A3&"*", 'Final set of papers'!$G$2:$G1000, "*"&Table1[[#HEADERS],[3- Security]]&"*" ) -> 9 | E3: =COUNTIFS( 'Final set of papers'!$F$2:$F1000, "*"&A3&"*", 'Final set of papers'!$G$2:$G1000, "*"&Table1[[#HEADERS],[4- Operational Quality]]&"*" ) -> 6 | F3: =COUNTIFS( 'Final set of papers'!$F$2:$F1000, "*"&A3&"*", 'Final set of papers'!$G$2:$G1000, "*"&Table1[[#HEADERS],[5- Performance & Resource management]]&"*" ) -> 1 | G3: =COUNTIFS( 'Final set of papers'!$F$2:$F1000, "*"&A3&"*", 'Final set of papers'!$G$2:$G1000, "*"&Table1[[#HEADERS],[6- Maintability & Documentation]]&"*" ) -> 6 | H3: =COUNTIFS( 'Final set of papers'!$F$2:$F1000, "*"&A3&"*", 'Final set of papers'!$G$2:$G1000, "*"&Table1[[#HEADERS],[7- Data & Variable management]]&"*" ) -> 6 | I3: =COUNTIFS( 'Final set of papers'!$F$2:$F1000, "*"&A3&"*", 'Final set of papers'!$G$2:$G1000, "*"&Table1[[#HEADERS],[8- Control Flow & Logic]]&"*" ) -> 4 | J3: =COUNTIFS( 'Final set of papers'!$F$2:$F1000, "*"&A3&"*", 'Final set of papers'!$G$2:$G1000, "*"&Table1[[#HEADERS],[9- Domain Specific Issues]]&"*" ) -> 3
A4: =IFERROR(__xludf.DUMMYFUNCTION("""COMPUTED_VALUE"""),"Multi (for TA)") -> Multi (for TA) | B4: =COUNTIFS( 'Final set of papers'!$F$2:$F1000, "*"&A4&"*", 'Final set of papers'!$G$2:$G1000, "*"&Table1[[#HEADERS],[1- Structural Quality]]&"*" ) -> 2 | C4: =COUNTIFS( 'Final set of papers'!$F$2:$F1000, "*"&A4&"*", 'Final set of papers'!$G$2:$G1000, "*"&Table1[[#HEADERS],[2- Syntactic & Linguistic Quality]]&"*" ) -> 2 | D4: =COUNTIFS( 'Final set of papers'!$F$2:$F1000, "*"&A4&"*", 'Final set of papers'!$G$2:$G1000, "*"&Table1[[#HEADERS],[3- Security]]&"*" ) -> 5 | E4: =COUNTIFS( 'Final set of papers'!$F$2:$F1000, "*"&A4&"*", 'Final set of papers'!$G$2:$G1000, "*"&Table1[[#HEADERS],[4- Operational Quality]]&"*" ) -> 2 | F4: =COUNTIFS( 'Final set of papers'!$F$2:$F1000, "*"&A4&"*", 'Final set of papers'!$G$2:$G1000, "*"&Table1[[#HEADERS],[5- Performance & Resource management]]&"*" ) -> 2 | G4: =COUNTIFS( 'Final set of papers'!$F$2:$F1000, "*"&A4&"*", 'Final set of papers'!$G$2:$G1000, "*"&Table1[[#HEADERS],[6- Maintability & Documentation]]&"*" ) -> 1 | H4: =COUNTIFS( 'Final set of papers'!$F$2:$F1000, "*"&A4&"*", 'Final set of papers'!$G$2:$G1000, "*"&Table1[[#HEADERS],[7- Data & Variable management]]&"*" ) -> 4 | I4: =COUNTIFS( 'Final set of papers'!$F$2:$F1000, "*"&A4&"*", 'Final set of papers'!$G$2:$G1000, "*"&Table1[[#HEADERS],[8- Control Flow & Logic]]&"*" ) -> 3 | J4: =COUNTIFS( 'Final set of papers'!$F$2:$F1000, "*"&A4&"*", 'Final set of papers'!$G$2:$G1000, "*"&Table1[[#HEADERS],[9- Domain Specific Issues]]&"*" ) -> 1
A5: =IFERROR(__xludf.DUMMYFUNCTION("""COMPUTED_VALUE"""),"Terraform") -> Terraform | B5: =COUNTIFS( 'Final set of papers'!$F$2:$F1000, "*"&A5&"*", 'Final set of papers'!$G$2:$G1000, "*"&Table1[[#HEADERS],[1- Structural Quality]]&"*" ) -> 4 | C5: =COUNTIFS( 'Final set of papers'!$F$2:$F1000, "*"&A5&"*", 'Final set of papers'!$G$2:$G1000, "*"&Table1[[#HEADERS],[2- Syntactic & Linguistic Quality]]&"*" ) -> 1 | D5: =COUNTIFS( 'Final set of papers'!$F$2:$F1000, "*"&A5&"*", 'Final set of papers'!$G$2:$G1000, "*"&Table1[[#HEADERS],[3- Security]]&"*" ) -> 3 | E5: =COUNTIFS( 'Final set of papers'!$F$2:$F1000, "*"&A5&"*", 'Final set of papers'!$G$2:$G1000, "*"&Table1[[#HEADERS],[4- Operational Quality]]&"*" ) -> 4 | F5: =COUNTIFS( 'Final set of papers'!$F$2:$F1000, "*"&A5&"*", 'Final set of papers'!$G$2:$G1000, "*"&Table1[[#HEADERS],[5- Performance & Resource management]]&"*" ) -> 2 | G5: =COUNTIFS( 'Final set of papers'!$F$2:$F1000, "*"&A5&"*", 'Final set of papers'!$G$2:$G1000, "*"&Table1[[#HEADERS],[6- Maintability & Documentation]]&"*" ) -> 2 | H5: =COUNTIFS( 'Final set of papers'!$F$2:$F1000, "*"&A5&"*", 'Final set of papers'!$G$2:$G1000, "*"&Table1[[#HEADERS],[7- Data & Variable management]]&"*" ) -> 1 | I5: =COUNTIFS( 'Final set of papers'!$F$2:$F1000, "*"&A5&"*", 'Final set of papers'!$G$2:$G1000, "*"&Table1[[#HEADERS],[8- Control Flow & Logic]]&"*" ) -> 1 | J5: =COUNTIFS( 'Final set of papers'!$F$2:$F1000, "*"&A5&"*", 'Final set of papers'!$G$2:$G1000, "*"&Table1[[#HEADERS],[9- Domain Specific Issues]]&"*" ) -> 2
A6: =IFERROR(__xludf.DUMMYFUNCTION("""COMPUTED_VALUE"""),"Chef") -> Chef | B6: =COUNTIFS( 'Final set of papers'!$F$2:$F1000, "*"&A6&"*", 'Final set of papers'!$G$2:$G1000, "*"&Table1[[#HEADERS],[1- Structural Quality]]&"*" ) -> 1 | C6: =COUNTIFS( 'Final set of papers'!$F$2:$F1000, "*"&A6&"*", 'Final set of papers'!$G$2:$G1000, "*"&Table1[[#HEADERS],[2- Syntactic & Linguistic Quality]]&"*" ) -> 2 | D6: =COUNTIFS( 'Final set of papers'!$F$2:$F1000, "*"&A6&"*", 'Final set of papers'!$G$2:$G1000, "*"&Table1[[#HEADERS],[3- Security]]&"*" ) -> 1 | E6: =COUNTIFS( 'Final set of papers'!$F$2:$F1000, "*"&A6&"*", 'Final set of papers'!$G$2:$G1000, "*"&Table1[[#HEADERS],[4- Operational Quality]]&"*" ) -> 0 | F6: =COUNTIFS( 'Final set of papers'!$F$2:$F1000, "*"&A6&"*", 'Final set of papers'!$G$2:$G1000, "*"&Table1[[#HEADERS],[5- Performance & Resource management]]&"*" ) -> 0 | G6: =COUNTIFS( 'Final set of papers'!$F$2:$F1000, "*"&A6&"*", 'Final set of papers'!$G$2:$G1000, "*"&Table1[[#HEADERS],[6- Maintability & Documentation]]&"*" ) -> 1 | H6: =COUNTIFS( 'Final set of papers'!$F$2:$F1000, "*"&A6&"*", 'Final set of papers'!$G$2:$G1000, "*"&Table1[[#HEADERS],[7- Data & Variable management]]&"*" ) -> 0 | I6: =COUNTIFS( 'Final set of papers'!$F$2:$F1000, "*"&A6&"*", 'Final set of papers'!$G$2:$G1000, "*"&Table1[[#HEADERS],[8- Control Flow & Logic]]&"*" ) -> 0 | J6: =COUNTIFS( 'Final set of papers'!$F$2:$F1000, "*"&A6&"*", 'Final set of papers'!$G$2:$G1000, "*"&Table1[[#HEADERS],[9- Domain Specific Issues]]&"*" ) -> 0
